Workbook

Sheet README
A1: CPI NOWCAST MODEL — bottom-up replica of the BLS aggregation (Sept 2026 print, released Oct 14 2026 8:30 ET)
A3: WHAT THIS IS
A4: A component-level model of the Consumer Price Index built the way the BLS builds it: each expenditure category gets a
A5: forecast monthly price change, those are weighted by relative importance, and the sum is the unrounded headline and core
A6: CPI. The unrounded result is then mapped to the one-decimal YoY figure Kalshi settles on, and a probability is assigned to
A7: each bracket so model odds can be compared to market prices. This is the same structure Brian Golden describes in the
A8: Bloomberg piece (Oct 13 2026): 'a bunch of good small guesses', not a macro view.
A10: HOW TO USE
A11: 1. Nowcast tab — blue cells are inputs. Change the NSA MoM forecast and standard error for any component.
A12: 2. Brackets tab — reads the Nowcast and shows model probability vs Kalshi price for every YoY bracket. Edge = model minus market.
A13: 3. Forecasters tab — consensus and bank forecasts converted to the same unrounded YoY scale so you can see who sits where.
A14: 4. Backtest tab — the tracking log. Fill in your forecast and consensus before each print; the sheet scores cumulative absolute error
... A39: Not financial advice. v4, built Oct 14 2026 from public BLS, Kalshi API, and published forecaster data (see Sources tab).

Sheet Data
A1: BLS CPI-U Table 1 — August 2026 release (Sept 11 2026) and September 2025 release (Oct 24 2025)
A2: Source: https://www.bls.gov/news.release/cpi.t01.htm and https://www.bls.gov/news.release/archives/cpi_10242025.htm. All values exactly as published.
A4: Category | B4: Rel. imp. Jul 2026 | C4: Index Aug 2025 | D4: Index Jul 2026 | E4: Index Aug 2026 | F4: YoY % Aug 26 | G4: NSA MoM % Aug 26 | H4: SA MoM % Jun | I4: SA MoM % Jul | J4: SA MoM % Aug | K4: SA? | M4: Rel. imp. Aug 2025 | N4: Index Sep 2025 | O4: NSA MoM % Sep 25 | P4: SA MoM % Jul 25 | Q4: SA MoM % Aug 25 | R4: SA MoM % Sep 25
A5: All items | B5: 100 | C5: 323.976 | D5: 333.918 | E5: 334.98 | F5: 3.4 | G5: 0.3 | H5: -0.4 | I5: 0.1 | J5: 0.4 | K5: SA | M5: 100 | N5: 324.8 | O5: 0.3 | P5: 0.2 | Q5: 0.4 | R5: 0.3
A6: Food | B6: 13.54 | C6: 341.295 | D6: 350.164 | E6: 350.418 | F6: 2.7 | G6: 0.1 | H6: 0.2 | I6: 0.1 | J6: 0.1 | K6: SA | M6: 13.646 | N6: 342.405 | O6: 0.3 | P6: 0 | Q6: 0.5 | R6: 0.2
A7: Food at home | B7: 8.232 | C7: 314.608 | D7: 321.643 | E7: 321.5 | F7: 2.2 | G7: 0 | H7: 0.2 | I7: -0.1 | J7: 0 | K7: SA | M7: 7.993 | N7: 316.042 | O7: 0.5 | P7: -0.1 | Q7: 0.6 | R7: 0.3
A8: Food away from home | B8: 5.307 | C8: 384.909 | D8: 396.859 | E8: 397.868 | F8: 3.4 | G8: 0.3 | H8: 0.2 | I8: 0.3 | J8: 0.3 | K8: NSA | M8: 5.653 | N8: 385.451 | O8: 0.1 | P8: 0.3 | Q8: 0.3 | R8: 0.1
A9: Energy | B9: 7.347 | C9: 283.247 | D9: 325.15 | E9: 329.351 | F9: 16.3 | G9: 1.3 | H9: -5.7 | I9: -1.5 | J9: 2.1 | K9: SA | M9: 6.4 | N9: 283.589 | O9: 0.1 | P9: -1.1 | Q9: 0.7 | R9: 1.5
A10: Energy commodities | B10: 4.044 | C10: 289.117 | D10: 359.754 | E10: 370.006 | F10: 28 | G10: 2.8 | H10: -9.5 | I10: -2.9 | J10: 4.2 | K10: SA | M10: 3.166 | N10: 292.19 | O10: 1.1 | P10: -1.9 | Q10: 1.7 | R10: 3.8
A11: Fuel oil | B11: 0.107 | C11: 347.565 | D11: 490.083 | E11: 528.436 | F11: 52 | G11: 7.8 | H11: -9.2 | I11: -1.7 | J11: 10.1 | K11: SA | M11: 0.074 | N11: 348.399 | O11: 0.2 | P11: 1.8 | Q11: -0.3 | R11: 0.6
A12: Motor fuel | B12: 3.882 | C12: 283.504 | D12: 352.826 | E12: 362.487 | F12: 27.9 | G12: 2.7 | H12: -9.6 | I12: -3 | J12: 4.1 | K12: SA | M12: 3.033 | N12: 286.672 | O12: 1.1 | P12: -2 | Q12: 1.8 | R12: 4
A13: Gasoline (all types) | B13: 3.77 | C13: 282.358 | D13: 350.846 | E13: 359.738 | F13: 27.4 | G13: 2.5 | H13: -9.7 | I13: -2.9 | J13: 3.9 | K13: SA | M13: 2.949 | N13: 285.595 | O13: 1.1 | P13: -2.2 | Q13: 1.9 | R13: 4.1
A14: Energy services | B14: 3.303 | C14: 289.154 | D14: 302.594 | E14: 300.729 | F14: 4 | G14: -0.6 | H14: -0.7 | I14: 0.3 | J14: -0.4 | K14: SA | M14: 3.235 | N14: 286.838 | O14: -0.8 | P14: -0.3 | Q14: -0.2 | R14: -0.7
A15: Electricity | B15: 2.551 | C15: 298.738 | D15: 311.672 | E15: 310.057 | F15: 3.8 | G15: -0.5 | H15: -1 | I15: 0.1 | J15: -0.2 | K15: SA | M15: 2.465 | N15: 296.887 | O15: -0.6 | P15: -0.1 | Q15: 0.2 | R15: -0.5
A16: Utility (piped) gas service | B16: 0.752 | C16: 255.253 | D16: 268.999 | E16: 266.448 | F16: 4.4 | G16: -0.9 | H16: 0.5 | I16: 0.7 | J16: -1.1 | K16: SA | M16: 0.77 | N16: 251.728 | O16: -1.4 | P16: -0.9 | Q16: -1.6 | R16: -1.2
... A35: Airline fares | B35: 1.049 | C35: 250.982 | D35: 311.176 | E35: 309.736 | F35: 23.4 | G35: -0.5 | H35: 0.2 | I35: 2.2 | J35: 2.7 | K35: SA | M35: 0.855 | N35: 258.027 | O35: 2.8 | P35: 4 | Q35: 5.9 | R35: 2.7
A37: Notes: Tobacco Aug-2026 release is on a Dec 2024=100 base (rebased); Sept 2025 release index is on the old base — the two are not comparable, only the % changes are.
A38: 'SA?' = whether BLS publishes a seasonally adjusted series for that category (NSA means SA column = NSA change).
A39: BLS 1-month standard error for all-items CPI-U: 0.04 (Aug 2026 release technical note). Table 7 (12-month) SE for all items: 0.09.

Sheet Nowcast
A1: September 2026 CPI Nowcast — bottom-up component model
A2: Blue = your inputs. Forecast NSA MoM is what you expect the raw index to do; the SA column is derived for comparison with bank forecasts. Change any blue cell and everything recalculates.
A4: Aug 2026 all-items index (NSA) | B4: =Data!E5 -> 334.98
A5: Sep 2025 all-items index (NSA, YoY base) | B5: =Data!N5 -> 324.8
A6: Aug 2026 core index (NSA) | B6: =Data!E17 -> 338.041
A7: Sep 2025 core index (NSA) | B7: =Data!N17 -> 330.804
A8: All-items NSA MoM Aug 2026 (for weight roll-forward) | B8: =B4/Data!D5-1 -> 0.0031804215
A9: BLS sampling SE, 1-month all items (pp) | B9: 0.04
A10: Model residual SE — things the components miss (pp) | B10: 0.05
A12: Component | B12: Rel. imp. Jul 2026 | C12: NSA MoM Aug 2026 | D12: Jul→Aug price relative | E12: Rel. imp. Aug 2026 (used) | F12: Forecast NSA MoM Sep (%) | G12: SE (pp) | H12: Sept SA−NSA gap (pp) | I12: Implied SA MoM (%) | J12: NSA contribution (pp) | K12: SA contribution (pp) | L12: Var contrib (w·se)² | N12: Rationale / data source
A13: Food at home | B13: =Data!B7 -> 8.232 | C13: =Data!E7/Data!D7-1 -> -0.0004445923 | D13: =(1+C13)/(1+$B$8) -> 0.99638648 | E13: =B13*D13 -> 8.2022535 | F13: 0.45 | G13: 0.25 | H13: -0.05 | I13: =F13+H13 -> 0.4 | J13: =E13*F13/100 -> 0.036910141 | K13: =E13*I13/100 -> 0.032809014 | L13: =(E13*G13/100)^2 -> 0.00042048101 | M13: F | N13: Aug was flat. Banks (Wells, DB) expect food to firm as transport costs pass through; SA ~+0.3. Sept 2025 seasonal gap −0.2.
A14: Food away from home | B14: =Data!B8 -> 5.307 | C14: =Data!E8/Data!D8-1 -> 0.0025424647 | D14: =(1+C14)/(1+$B$8) -> 0.99936407 | E14: =B14*D14 -> 5.3036251 | F14: 0.3 | G14: 0.1 | H14: 0 | I14: =F14+H14 -> 0.3 | J14: =E14*F14/100 -> 0.015910875 | K14: =E14*I14/100 -> 0.015910875 | L14: =(E14*G14/100)^2 -> 2.8128439e-05 | M14: F | N14: Very stable series: 0.2–0.3 every month in 2026. Not seasonally adjusted.
A15: Gasoline (all types) | B15: =Data!B13 -> 3.77 | C15: =Data!E13/Data!D13-1 -> 0.025344453 | D15: =(1+C15)/(1+$B$8) -> 1.0220938 | E15: =B15*D15 -> 3.8532935 | F15: 7.2 | G15: 0.6 | H15: 2.42 | I15: =F15+H15 -> 9.62 | J15: =E15*F15/100 -> 0.27743713 | K15: =E15*I15/100 -> 0.37068683 | L15: =(E15*G15/100)^2 -> 0.00053452335 | M15: E | N15: AAA Sept avg $4.33–4.36 vs Aug, +7.3% (stocktitan, Admiral Markets). XTech +7.4% NSA / +10% SA. DB +9.6% SA motor fuel. CPI sample timing can differ from weekly averages, hence SE 1.2. Official 2026 BLS factor: Aug 104.221 / Sep 101.759 → SA−NSA gap +2.42. EIA weekly avg Sept +7.31% vs Aug; EIA tracks CPI gasoline NSA within ~0.7pp (Sep25: 1.06 vs 1.15; Aug26: 3.2 vs 2.5).
A16: Other motor fuel (diesel etc.) | B16: =Data!B12-Data!B13 -> 0.112 | C16: =Data!E12/Data!D12-1 -> 0.027381769 | D16: =(1+C16)/(1+$B$8) -> 1.0241246 | E16: =B16*D16 -> 0.11470196 | F16: 5 | G16: 1.5 | H16: 2.4 | I16: =F16+H16 -> 7.4 | J16: =E16*F16/100 -> 0.0057350979 | K16: =E16*I16/100 -> 0.0084879449 | L16: =(E16*G16/100)^2 -> 2.9602213e-06 | M16: E | N16: Residual of motor fuel less gasoline (0.112). Tracks diesel; moves with gasoline.
A17: Fuel oil & other fuels | B17: =Data!B11+0.055 -> 0.162 | C17: =Data!E11/Data!D11-1 -> 0.078258173 | D17: =(1+C17)/(1+$B$8) -> 1.0748397 | E17: =B17*D17 -> 0.17412404 | F17: 4 | G17: 2 | H17: -0.05 | I17: =F17+H17 -> 3.95 | J17: =E17*F17/100 -> 0.0069649614 | K17: =E17*I17/100 -> 0.0068778994 | L17: =(E17*G17/100)^2 -> 1.2127672e-05 | M17: E | N17: Fuel oil 0.107 + propane/kerosene/firewood 0.055 (Table 7). Fuel oil +7.8% NSA in Aug; distillate still rising.
A18: Electricity | B18: =Data!B15 -> 2.551 | C18: =Data!E15/Data!D15-1 -> -0.0051817295 | D18: =(1+C18)/(1+$B$8) -> 0.99166436 | E18: =B18*D18 -> 2.5297358 | F18: -0.5 | G18: 0.4 | H18: 0.31 | I18: =F18+H18 -> -0.19 | J18: =E18*F18/100 -> -0.012648679 | K18: =E18*I18/100 -> -0.004806498 | L18: =(E18*G18/100)^2 -> 0.00010239301 | M18: E | N18: Sept NSA typically −0.5 to −0.6 as summer rates roll off (Sept 2025: −0.6 NSA, −0.5 SA).
A19: Utility (piped) gas service | B19: =Data!B16 -> 0.752 | C19: =Data!E16/Data!D16-1 -> -0.0094833066 | D19: =(1+C19)/(1+$B$8) -> 0.98737642 | E19: =B19*D19 -> 0.74250707 | F19: -1 | G19: 0.8 | H19: 0.51 | I19: =F19+H19 -> -0.49 | J19: =E19*F19/100 -> -0.0074250707 | K19: =E19*I19/100 -> -0.0036382846 | L19: =(E19*G19/100)^2 -> 3.5284272e-05 | M19: E | N19: Sept 2025: −1.4 NSA / −1.2 SA. Aug 2026 −1.1 SA.
A20: Apparel | B20: =Data!B19 -> 2.406 | C20: =Data!E19/Data!D19-1 -> 0.019153091 | D20: =(1+C20)/(1+$B$8) -> 1.015922 | E20: =B20*D20 -> 2.4443084 | F20: 2.1 | G20: 0.7 | H20: -2.1 | I20: =F20+H20 -> 0 | J20: =E20*F20/100 -> 0.051330477 | K20: =E20*I20/100 -> 0 | L20: =(E20*G20/100)^2 -> 0.00029275754 | M20: G | N20: Biggest seasonal in the basket: fall lines arrive in Sept. Official 2026 factors: women's apparel gap −2.65, men's −1.76, footwear −1.11 → weighted ≈ −2.1. Forecast SA 0.0.
A21: New vehicles | B21: =Data!B20 -> 3.756 | C21: =Data!E20/Data!D20-1 -> 0.00096913797 | D21: =(1+C21)/(1+$B$8) -> 0.99779573 | E21: =B21*D21 -> 3.7477208 | F21: 0.1 | G21: 0.2 | H21: 0.12 | I21: =F21+H21 -> 0.22 | J21: =E21*F21/100 -> 0.0037477208 | K21: =E21*I21/100 -> 0.0082449857 | L21: =(E21*G21/100)^2 -> 5.6181643e-05 | M21: G | N21: Model-year changeover; SA +0.2–0.3 recent. Sept 2025 NSA 0.0 / SA +0.2.
A22: Used cars and trucks | B22: =Data!B21 -> 2.698 | C22: =Data!E21/Data!D21-1 -> -0.00043864162 | D22: =(1+C22)/(1+$B$8) -> 0.99639241 | E22: =B22*D22 -> 2.6882667 | F22: -1.2 | G22: 0.6 | H22: 0.77 | I22: =F22+H22 -> -0.43 | J22: =E22*F22/100 -> -0.032259201 | K22: =E22*I22/100 -> -0.011559547 | L22: =(E22*G22/100)^2 -> 0.00026016401 | M22: G | N22: Manheim −1.1% in Sept to 205.9; wholesale leads CPI by ~2 months and has fallen 3 straight months (XTech, Admiral). Forecast SA −0.5. Sept 2025 gap +0.6.
A23: Medical care commodities | B23: =Data!B22 -> 1.403 | C23: =Data!E22/Data!D22-1 -> -0.0022978778 | D23: =(1+C23)/(1+$B$8) -> 0.99453907 | E23: =B23*D23 -> 1.3953383 | F23: -0.2 | G23: 0.4 | H23: 0 | I23: =F23+H23 -> -0.2 | J23: =E23*F23/100 -> -0.0027906766 | K23: =E23*I23/100 -> -0.0027906766 | L23: =(E23*G23/100)^2 -> 3.1151504e-05 | M23: G | N23: Down 6 of last 7 months. NSA series.
A24: Alcoholic beverages | B24: =Data!B23 -> 0.825 | C24: =Data!E23/Data!D23-1 -> 0.0011846022 | D24: =(1+C24)/(1+$B$8) -> 0.99801051 | E24: =B24*D24 -> 0.82335867 | F24: 0.2 | G24: 0.2 | H24: -0.05 | I24: =F24+H24 -> 0.15 | J24: =E24*F24/100 -> 0.0016467173 | K24: =E24*I24/100 -> 0.001235038 | L24: =(E24*G24/100)^2 -> 2.711678e-06 | M24: G | N24: Stable. NSA series.
A25: Tobacco and smoking products | B25: =Data!B24 -> 0.448 | C25: =Data!E24/Data!D24-1 -> 0.0063656832 | D25: =(1+C25)/(1+$B$8) -> 1.0031752 | E25: =B25*D25 -> 0.44942247 | F25: 0.5 | G25: 0.4 | H25: 0 | I25: =F25+H25 -> 0.5 | J25: =E25*F25/100 -> 0.0022471124 | K25: =E25*I25/100 -> 0.0022471124 | L25: =(E25*G25/100)^2 -> 3.2316889e-06 | M25: G | N25: Trend +0.5/mo. NSA series.
A26: Rent of primary residence | B26: =Data!B27 -> 7.735 | C26: =Data!E27/Data!D27-1 -> 0.0023082263 | D26: =(1+C26)/(1+$B$8) -> 0.99913057 | E26: =B26*D26 -> 7.728275 | F26: 0.35 | G26: 0.1 | H26: -0.07 | I26: =F26+H26 -> 0.28 | J26: =E26*F26/100 -> 0.027048962 | K26: =E26*I26/100 -> 0.02163917 | L26: =(E26*G26/100)^2 -> 5.9726234e-05 | M26: S | N26: SA 0.2–0.3 range all year (Aug 0.2, Jul 0.3). Forecast SA 0.3. Sept 2025 gap −0.1. Rent is a 6-month panel so it moves slowly.
A27: Owners' equivalent rent | B27: =Data!B28 -> 25.918 | C27: =Data!E28/Data!D28-1 -> 0.0025739938 | D27: =(1+C27)/(1+$B$8) -> 0.99939549 | E27: =B27*D27 -> 25.902332 | F27: 0.34 | G27: 0.08 | H27: -0.04 | I27: =F27+H27 -> 0.3 | J27: =E27*F27/100 -> 0.08806793 | K27: =E27*I27/100 -> 0.077706997 | L27: =(E27*G27/100)^2 -> 0.00042939573 | M27: S | N27: 25.9% of the index — the single most important cell. SA 0.2 Aug, 0.3 Jul; Sept 2025 printed 0.1 SA (lowest since 2021). Forecast SA 0.3.
A28: Other shelter (lodging away, tenants' ins.) | B28: =Data!B26-Data!B27-Data!B28 -> 1.69 | C28: =Data!E26/Data!D26-1 -> 0.002607738 | D28: =(1+C28)/(1+$B$8) -> 0.99942913 | E28: =B28*D28 -> 1.6890352 | F28: -2.3 | G28: 1.8 | H28: 2.9 | I28: =F28+H28 -> 0.6 | J28: =E28*F28/100 -> -0.03884781 | K28: =E28*I28/100 -> 0.010134211 | L28: =(E28*G28/100)^2 -> 0.00092432017 | M28: S | N28: Official factor for hotels/motels: Aug 103.515 / Sep 100.579 → gap +2.92. Lodging +2.4 Aug after −2.8 Jul. Forecast SA +0.6. Residual weight 1.690.
A29: Medical care services | B29: =Data!B29 -> 6.864 | C29: =Data!E29/Data!D29-1 -> -0.0011064466 | D29: =(1+C29)/(1+$B$8) -> 0.99572672 | E29: =B29*D29 -> 6.8346682 | F29: 0.2 | G29: 0.3 | H29: 0.02 | I29: =F29+H29 -> 0.22 | J29: =E29*F29/100 -> 0.013669336 | K29: =E29*I29/100 -> 0.01503627 | L29: =(E29*G29/100)^2 -> 0.00042041421 | M29: S | N29: −0.2 Aug after +0.6 Jul; dental fell. Forecast SA +0.2.
A30: Motor vehicle insurance | B30: =Data!B34 -> 2.563 | C30: =Data!E34/Data!D34-1 -> -0.0091685357 | D30: =(1+C30)/(1+$B$8) -> 0.98769019 | E30: =B30*D30 -> 2.53145 | F30: -0.8 | G30: 0.5 | H30: 0.32 | I30: =F30+H30 -> -0.48 | J30: =E30*F30/100 -> -0.0202516 | K30: =E30*I30/100 -> -0.01215096 | L30: =(E30*G30/100)^2 -> 0.00016020597 | M30: S | N30: Falling: −2.0 Jun, −0.3 Jul, −0.8 Aug. XTech: softer insurance. Forecast −0.5.
A31: Airline fares | B31: =Data!B35 -> 1.049 | C31: =Data!E35/Data!D35-1 -> -0.0046276062 | D31: =(1+C31)/(1+$B$8) -> 0.99221673 | E31: =B31*D31 -> 1.0408353 | F31: 2.3 | G31: 2 | H31: -0.83 | I31: =F31+H31 -> 1.47 | J31: =E31*F31/100 -> 0.023939213 | K31: =E31*I31/100 -> 0.01530028 | L31: =(E31*G31/100)^2 -> 0.00043333529 | M31: S | N31: Main upside risk per Admiral/XTech: jet fuel high. +2.7 Aug, +2.2 Jul. Noisy series (SE 2.5). Forecast SA +1.5.
A32: Motor vehicle maintenance & repair | B32: =Data!B33 -> 1.055 | C32: =Data!E33/Data!D33-1 -> 0.010758717 | D32: =(1+C32)/(1+$B$8) -> 1.0075543 | E32: =B32*D32 -> 1.0629698 | F32: 0.4 | G32: 0.4 | H32: 0 | I32: =F32+H32 -> 0.4 | J32: =E32*F32/100 -> 0.004251879 | K32: =E32*I32/100 -> 0.004251879 | L32: =(E32*G32/100)^2 -> 1.8078475e-05 | M32: S | N32: +1.1 Aug, +0.6 Jul. NSA series. Forecast +0.4.
A33: Other transportation services (residual) | B33: =Data!B32-Data!B33-Data!B34-Data!B35 -> 1.643 | C33: =Data!E32/Data!D32-1 -> -0.0045542218 | D33: =(1+C33)/(1+$B$8) -> 0.99228988 | E33: =B33*D33 -> 1.6303323 | F33: 0 | G33: 0.5 | H33: 0.3 | I33: =F33+H33 -> 0.3 | J33: =E33*F33/100 -> 0 | K33: =E33*I33/100 -> 0.0048909968 | L33: =(E33*G33/100)^2 -> 6.6449583e-05 | M33: S | N33: Parking, tolls, vehicle fees, public transit, car rental. Residual weight 1.643.
A34: Household furnishings & operations | B34: 4.245 | C34: -0.001 | D34: =(1+C34)/(1+$B$8) -> 0.99583283 | E34: =B34*D34 -> 4.2273104 | F34: 0.13 | G34: 0.3 | H34: -0.18 | I34: =F34+H34 -> -0.05 | J34: =E34*F34/100 -> 0.0054955035 | K34: =E34*I34/100 -> -0.0021136552 | L34: =(E34*G34/100)^2 -> 0.00016083138 | M34: G | N34: BLS Table 3 aggregate (Jul-26 weight 4.245). Last-4 SA: −0.6, 0.2, 0.1, 0.1. Sept gap from furnishings/moving factors −0.18. Backtest: this category was in the unmodeled residual before v4.
A35: Recreation | B35: 5.081 | C35: -0.0004 | D35: =(1+C35)/(1+$B$8) -> 0.99643093 | E35: =B35*D35 -> 5.0628656 | F35: 0.33 | G35: 0.3 | H35: -0.08 | I35: =F35+H35 -> 0.25 | J35: =E35*F35/100 -> 0.016707456 | K35: =E35*I35/100 -> 0.012657164 | L35: =(E35*G35/100)^2 -> 0.00023069347 | M35: S | N35: Table 3 aggregate. Last-4 SA: 0.3, 0.5, 0.2, 0.0. Gap −0.08 from toys/pets/cable/club/TV factors.
A36: Education | B36: 2.552 | C36: 0.0137 | D36: =(1+C36)/(1+$B$8) -> 1.0104862 | E36: =B36*D36 -> 2.5787609 | F36: 0.98 | G36: 0.4 | H36: -0.63 | I36: =F36+H36 -> 0.35 | J36: =E36*F36/100 -> 0.025271856 | K36: =E36*I36/100 -> 0.009025663 | L36: =(E36*G36/100)^2 -> 0.00010640012 | M36: S | N36: Tuition month: Sept NSA is seasonally strong (gap −0.63 from tuition/childcare factor). Last-4 SA 0.0, 0.1, 0.5, 0.8 → trend 0.35 + 0.63 = 0.98 NSA.
A37: Communication | B37: 3.164 | C37: 0.0233 | D37: =(1+C37)/(1+$B$8) -> 1.0200558 | E37: =B37*D37 -> 3.2274565 | F37: 0 | G37: 0.6 | H37: 0.4 | I37: =F37+H37 -> 0.4 | J37: =E37*F37/100 -> 0 | K37: =E37*I37/100 -> 0.012909826 | L37: =(E37*G37/100)^2 -> 0.00037499312 | M37: S | N37: Aug +2.33 NSA was a wireless-plan price jump. 4-mo trend says +0.28; DB and Wells expect partial reversal. Judgment: 0.0 (SE 0.6 because this series swings).
A38: Other goods and services (personal care etc.) | B38: 2.907 | C38: 0.0009 | D38: =(1+C38)/(1+$B$8) -> 0.99772681 | E38: =B38*D38 -> 2.9003918 | F38: 0.36 | G38: 0.3 | H38: -0.01 | I38: =F38+H38 -> 0.35 | J38: =E38*F38/100 -> 0.010441411 | K38: =E38*I38/100 -> 0.010151371 | L38: =(E38*G38/100)^2 -> 7.5710455e-05 | M38: S | N38: Table 3 aggregate. Last-4 SA 1.0, 0.1, 0.1, 0.2. Personal care factor gap ≈ 0.
A39: Unmodeled remainder (water/sewer, tenants ins., misc.) | B39: =Data!B18+Data!B25-Data!B19-Data!B20-Data!B21-Data!B22-Data!B23-Data!B24-Data!B26-Data!B29-Data!B32-4.245-5.081-2.552-3.164-2.907 -> 1.112 | C39: =Data!E18/Data!D18-1 -> 0.0028373941 | D39: =(1+C39)/(1+$B$8) -> 0.99965806 | E39: =B39*D39 -> 1.1116198 | F39: 0.3 | G39: 0.3 | H39: 0 | I39: =F39+H39 -> 0.3 | J39: =E39*F39/100 -> 0.0033348593 | K39: =E39*I39/100 -> 0.0033348593 | L39: =(E39*G39/100)^2 -> 1.1121286e-05 | M39: S | N39: What is left of core after every modeled line: water/sewer/trash, tenants' insurance, misc. Should be ~5–6 points of weight. Trend core, no seasonal.
A40: Check: weights sum (Jul / Aug-rolled) | B40: =SUM(B13:B39) -> 100 | E40: =SUM(E13:E39) -> 99.996959
A42: HEADLINE (all items)
A43: Forecast NSA MoM, Sept 2026 (%) | B43: =SUM(J13:J39)/E40*100 -> 0.50595099
...

Sheet Opportunities
A1: Kalshi CPI markets scanned Oct 14 2026 ~10:00 ET — every contract where the model's edge after fees ≥ 5 points
A2: Edge = model probability − price you pay − ~1.75¢ fee. Model centers: Oct headline SA +0.17, Oct core SA +0.20, Nov YoY 3.99, Dec YoY 3.95, Nov core YoY 2.82, Dec core YoY 2.77, Dec grocery YoY 2.24. Prices are a snapshot; re-quote before trading. Not financial advice.
A4: Market | B4: Contract ticker | C4: Strike | D4: Side | E4: Pay ($) | F4: Model P | G4: Edge | H4: Model μ | I4: SD | J4: Confidence / main risk | K4: OI | L4: Closes | M4: Note
A5: Dec food-at-home YoY | B5: KXGROCERYCPI-27JAN13-T3.0 | C5: Above 3.0% | D5: NO | E5: 0.63 | F5: 0.92958771 | G5: 0.28208771 | H5: 2.24 | I5: 0.55 | J5: C — thin book, wide spread, food is noisy | K5: 221.97 | L5: 2027-01-13 | M5: As above. 3.0+ needs +0.5/mo; very unlikely absent a food shock.
A6: Dec food-at-home YoY | B6: KXGROCERYCPI-27JAN13-T2.5 | C6: Above 2.5% | D6: NO | E6: 0.45 | F6: 0.71349918 | G6: 0.24599918 | H6: 2.24 | I6: 0.55 | J6: C — thin book, wide spread, food is noisy | K6: 1220.12 | L6: 2027-01-13 | M6: Food at home YoY just printed 1.8 and the 6-mo SA trend is ~0. Reaching 2.5+ by Dec needs +0.3/mo for three months. Book is thin (OI 1.2k) and spread is 9¢ wide; work the bid.
A7: Dec food-at-home YoY | B7: KXGROCERYCPI-27JAN13-T3.5 | C7: Above 3.5% | D7: NO | E7: 0.76 | F7: 0.9913863 | G7: 0.2138863 | H7: 2.24 | I7: 0.55 | J7: C — thin book, wide spread, food is noisy | K7: 409.81 | L7: 2027-01-13
A8: Nov headline YoY | B8: KXCPIYOY-26NOV-T3.7 | C8: Above 3.7% | D8: YES | E8: 0.69 | F8: 0.87928295 | G8: 0.17178295 | H8: 3.9904252 | I8: 0.20524432 | J8: B — structural base effect; gasoline Oct–Nov is the risk | K8: 6677.98 | L8: 2026-12-10 | M8: Structural: Nov-2025 base (324.122) sits BELOW Sept-2025 (324.800) because of the shutdown/Black-Friday collection. A flat index Sept→Nov already gives 3.95%. Market center ~3.85 needs the index to FALL ~0.1% in two months.
A9: Dec headline YoY | B9: KXCPIYOY-26DEC-T3.8 | C9: Above 3.8% | D9: YES | E9: 0.46 | F9: 0.64249005 | G9: 0.16499005 | H9: 3.9473853 | I9: 0.26671941 | J9: C — three months of gasoline unknown | K9: 33603.32 | L9: 2027-01-13 | M9: Three months of gasoline unknown (SD 0.27). Smaller size than the Nov equivalents.
A10: Nov headline YoY | B10: KXCPIYOY-26NOV-T3.6 | C10: Above 3.6% | D10: YES | E10: 0.78 | F10: 0.95140522 | G10: 0.15390522 | H10: 3.9904252 | I10: 0.20524432 | J10: B — structural base effect; gasoline Oct–Nov is the risk | K10: 2174.47 | L10: 2026-12-10 | M10: Same base-effect logic. Needs Oct+Nov NSA to be worse than −0.3% combined to lose; that would take gasoline −8% or so.
A11: Dec headline YoY | B11: KXCPIYOY-26DEC-T3.7 | C11: Above 3.7% | D11: YES | E11: 0.61 | F11: 0.77036469 | G11: 0.14286469 | H11: 3.9473853 | I11: 0.26671941 | J11: C — three months of gasoline unknown | K11: 2336.45 | L11: 2027-01-13
A12: Dec headline YoY | B12: KXCPIYOY-26DEC-T3.6 | C12: Above 3.6% | D12: YES | E12: 0.71 | F12: 0.86756927 | G12: 0.14006927 | H12: 3.9473853 | I12: 0.26671941 | J12: C — three months of gasoline unknown | K12: 776.81 | L12: 2027-01-13
A13: Nov headline YoY | B13: KXCPIYOY-26NOV-T4.0 | C13: Above 4.0% | D13: YES | E13: 0.23 | F13: 0.3858076 | G13: 0.1383076 | H13: 3.9904252 | I13: 0.20524432 | J13: B — structural base effect; gasoline Oct–Nov is the risk | K13: 30746.5 | L13: 2026-12-10
A14: Dec core YoY | B14: KXCPICOREYOY-26DEC-T2.9 | C14: Above 2.9% | D14: NO | E14: 0.73 | F14: 0.8793303 | G14: 0.1318303 | H14: 2.7742532 | I14: 0.15 | J14: C | K14: 1202.01 | L14: 2027-01-13
A15: Nov core YoY | B15: KXCPICOREYOY-26NOV-T2.5 | C15: Above 2.5% | D15: YES | E15: 0.84 | F15: 0.98775414 | G15: 0.13025414 | H15: 2.8199192 | I15: 0.12 | J15: B | K15: 3400.02 | L15: 2026-12-10
A16: Oct core SA MoM | B16: KXCPICORE-26OCT-T0.2 | C16: Above 0.2% | D16: NO | E16: 0.54 | F16: 0.68587459 | G16: 0.12837459 | H16: 0.20158097 | I16: 0.1 | J16: A — hinges on 4-mo (0.2) vs 2-mo (0.3) core trend | K16: 45424.15 | L16: 2026-11-10 | M16: Model core 0.20 uses 4-mo trend (0.0,0.2,0.3,0.3). If you believe the last two months (0.3) the edge disappears. Sept printed 0.3.
A17: Nov headline YoY | B17: KXCPIYOY-26NOV-T3.8 | C17: Above 3.8% | D17: YES | E17: 0.61 | F17: 0.75307101 | G17: 0.12557101 | H17: 3.9904252 | I17: 0.20524432 | J17: B — structural base effect; gasoline Oct–Nov is the risk | K17: 51875.08 | L17: 2026-12-10 | M17: Largest OI in the series (52k) — this is where the big players sit. Same base effect; thinner margin.
A18: Dec core YoY | B18: KXCPICOREYOY-26DEC-T2.5 | C18: Above 2.5% | D18: YES | E18: 0.79 | F18: 0.93254554 | G18: 0.12504554 | H18: 2.7742532 | I18: 0.15 | J18: C | K18: 7665.88 | L18: 2027-01-13
A19: Dec headline YoY | B19: KXCPIYOY-26DEC-T3.4 | C19: Above 3.4% | D19: YES | E19: 0.83 | F19: 0.9688971 | G19: 0.1213971 | H19: 3.9473853 | I19: 0.26671941 | J19: C — three months of gasoline unknown | K19: 3613.34 | L19: 2027-01-13
A20: Oct headline SA MoM | B20: KXCPI-26OCT-T0.1 | C20: Above 0.1% | D20: YES | E20: 0.44 | F20: 0.57361273 | G20: 0.11611273 | H20: 0.17226954 | I20: 0.12 | J20: A — one month out, EIA gasoline in hand | K20: 27052.76 | L20: 2026-11-10 | M20: Gasoline Oct-to-date −0.3% NSA = +1.5% SA after the Oct seasonal. Headline SA gap estimated from Oct 2024 only (+0.09). Medium confidence.
A21: Dec core YoY | B21: KXCPICOREYOY-26DEC-T2.8 | C21: Above 2.8% | D21: NO | E21: 0.56 | F21: 0.69321315 | G21: 0.11571315 | H21: 2.7742532 | I21: 0.15 | J21: C | K21: 2326.16 | L21: 2027-01-13
A22: Oct core SA MoM | B22: KXCPICORE-26OCT-T0.3 | C22: Above 0.3% | D22: NO | E22: 0.8 | F22: 0.93112078 | G22: 0.11362078 | H22: 0.20158097 | I22: 0.1 | J22: A — hinges on 4-mo (0.2) vs 2-mo (0.3) core trend | K22: 24897.21 | L22: 2026-11-10
A23: Dec headline YoY | B23: KXCPIYOY-26DEC-T3.5 | C23: Above 3.5% | D23: YES | E23: 0.81 | F23: 0.93187475 | G23: 0.10437475 | H23: 3.9473853 | I23: 0.26671941 | J23: C — three months of gasoline unknown | K23: 4286.25 | L23: 2027-01-13
A24: Nov headline YoY | B24: KXCPIYOY-26NOV-T3.9 | C24: Above 3.9% | D24: YES | E24: 0.46 | F24: 0.57807113 | G24: 0.10057113 | H24: 3.9904252 | I24: 0.20524432 | J24: B — structural base effect; gasoline Oct–Nov is the risk | K24: 33708.55 | L24: 2026-12-10
A25: Dec core YoY | B25: KXCPICOREYOY-26DEC-T2.4 | C25: Above 2.4% | D25: YES | E25: 0.87 | F25: 0.98467888 | G25: 0.097178876 | H25: 2.7742532 | I25: 0.15 | J25: C | K25: 1209 | L25: 2027-01-13
A26: Nov headline YoY | B26: KXCPIYOY-26NOV-T3.5 | C26: Above 3.5% | D26: YES | E26: 0.87 | F26: 0.98405785 | G26: 0.096557853 | H26: 3.9904252 | I26: 0.20524432 | J26: B — structural base effect; gasoline Oct–Nov is the risk | K26: 2088.21 | L26: 2026-12-10
A27: Nov core YoY | B27: KXCPICOREYOY-26NOV-T2.6 | C27: Above 2.6% | D27: YES | E27: 0.81 | F27: 0.92161129 | G27: 0.094111292 | H27: 2.8199192 | I27: 0.12 | J27: B | K27: 7554.03 | L27: 2026-12-10
A28: Dec headline YoY | B28: KXCPIYOY-26DEC-T4.0 | C28: Above 4.0% | D28: YES | E28: 0.25 | F28: 0.35021907 | G28: 0.082719066 | H28: 3.9473853 | I28: 0.26671941 | J28: C — three months of gasoline unknown | K28: 8268.59 | L28: 2027-01-13
A29: Dec headline YoY | B29: KXCPIYOY-26DEC-T3.2 | C29: Above 3.2% | D29: YES | E29: 0.9 | F29: 0.99553441 | G29: 0.078034415 | H29: 3.9473853 | I29: 0.26671941 | J29: C — three months of gasoline unknown | K29: 2007 | L29: 2027-01-13
A30: Dec headline YoY | B30: KXCPIYOY-26DEC-T3.3 | C30: Above 3.3% | D30: YES | E30: 0.9 | F30: 0.98744648 | G30: 0.069946479 | H30: 3.9473853 | I30: 0.26671941 | J30: C — three months of gasoline unknown | K30: 4183.42 | L30: 2027-01-13
A31: Dec core YoY | B31: KXCPICOREYOY-26DEC-T3.0 | C31: Above 3.0% | D31: NO | E31: 0.88 | F31: 0.96699179 | G31: 0.069491791 | H31: 2.7742532 | I31: 0.15 | J31: C | K31: 5562.77 | L31: 2027-01-13
A32: Dec headline YoY | B32: KXCPIYOY-26DEC-T3.9 | C32: Above 3.9% | D32: YES | E32: 0.41 | F32: 0.49608913 | G32: 0.068589128 | H32: 3.9473853 | I32: 0.26671941 | J32: C — three months of gasoline unknown | K32: 27320.48 | L32: 2027-01-13
... A39: Dec headline YoY | B39: KXCPIYOY-26DEC-T3.1 | C39: Above 3.1% | D39: YES | E39: 0.93 | F39: 0.9986033 | G39: 0.051103301 | H39: 3.9473853 | I39: 0.26671941 | J39: C — three months of gasoline unknown | K39: 2454 | L39: 2027-01-13
A41: HOW TO USE
A42: Confidence A = next print, inputs in hand. B = two prints out, one structural driver. C = three months out or a thin/noisy market; halve the size.
A43: Don't stack correlated bets: every Nov/Dec YoY contract is the same gasoline bet. Pick one or two strikes per event, not the ladder.
A44: The model's bias ran +0.02 hot in backtest and the Sept miss was −0.08 (too cool). Treat μ as ±0.05 fuzzy before you even get to the SD.
A46: Re-run after every Monday EIA print; the Nov/Dec YoY edges can evaporate in a week if pump prices fall 3%.
A47: A print that goes against you on Oct 14's core (0.3) already moved KXCPICORE-26OCT: that's why 'Above 0.2' is 46/47 instead of 30. The market reacts faster than the model's 4-mo trend; that cuts both ways.

Sheet Backtest
A1: Out-of-sample backtest — 69 prints, Nov 2020 – Sep 2026 (Oct 2025 unpublished)
A2: Each row uses only data published before that release: first-published SA changes (not later revisions), carried-forward weights, official 2026 seasonal factors, EIA weekly gasoline for the target month. Trend window = 4 months. No judgment overrides. SA model = NSA model + realized all-items SA−NSA gap.
A4: Ref. month | B4: Actual NSA | C4: Model NSA | D4: Error | E4: Actual YoY | F4: Model YoY | G4: Rounded YoY err | H4: Actual SA | I4: Model SA | J4: |SA err| rounded | K4: Cum |SA err| | L4: Period
A5: 2020-11 | B5: -0.061062722 | C5: -0.10923267 | D5: =C5-B5 -> -0.048169944 | G5: =IF(E5="","",ROUND(ROUND(F5,1)-ROUND(E5,1),1)) | H5: 0.2 | I5: 0.15183006 | J5: =IF(H5="","",ABS(ROUND(I5,1)-H5)) -> 0 | K5: =SUM(J$5:J5) -> 0 | L5: 2021 reopening
A6: 2020-12 | B6: 0.094147847 | C6: 0.030728186 | D6: =C6-B6 -> -0.063419661 | E6: 1.3620055 | F6: 1.2977825 | G6: =IF(E6="","",ROUND(ROUND(F6,1)-ROUND(E6,1),1)) -> -0.1 | H6: 0.4 | I6: 0.33658034 | J6: =IF(H6="","",ABS(ROUND(I6,1)-H6)) -> 0.1 | K6: =SUM(J$5:J6) -> 0.1 | L6: 2021 reopening
A7: 2021-01 | B7: 0.42537835 | C7: 0.49421623 | D7: =C7-B7 -> 0.068837881 | G7: =IF(E7="","",ROUND(ROUND(F7,1)-ROUND(E7,1),1)) | H7: 0.3 | I7: 0.36883788 | J7: =IF(H7="","",ABS(ROUND(I7,1)-H7)) -> 0.1 | K7: =SUM(J$5:J7) -> 0.2 | L7: 2021 reopening
A8: 2021-02 | B8: 0.54743828 | C8: 0.4537707 | D8: =C8-B8 -> -0.093667579 | E8: 1.6762152 | F8: 1.5814961 | G8: =IF(E8="","",ROUND(ROUND(F8,1)-ROUND(E8,1),1)) -> -0.1 | H8: 0.4 | I8: 0.30633242 | J8: =IF(H8="","",ABS(ROUND(I8,1)-H8)) -> 0.1 | K8: =SUM(J$5:J8) -> 0.3 | L8: 2021 reopening
A9: 2021-03 | B9: 0.70832731 | C9: 0.51972339 | D9: =C9-B9 -> -0.18860392 | G9: =IF(E9="","",ROUND(ROUND(F9,1)-ROUND(E9,1),1)) | H9: 0.6 | I9: 0.41139608 | J9: =IF(H9="","",ABS(ROUND(I9,1)-H9)) -> 0.2 | K9: =SUM(J$5:J9) -> 0.5 | L9: 2021 reopening
A10: 2021-04 | B10: 0.82189092 | C10: 0.20140375 | D10: =C10-B10 -> -0.62048716 | E10: 4.1596948 | F10: 3.5186659 | G10: =IF(E10="","",ROUND(ROUND(F10,1)-ROUND(E10,1),1)) -> -0.7 | H10: 0.8 | I10: 0.17951284 | J10: =IF(H10="","",ABS(ROUND(I10,1)-H10)) -> 0.6 | K10: =SUM(J$5:J10) -> 1.1 | L10: 2021 reopening
A11: 2021-05 | B11: 0.80171052 | C11: 0.49619609 | D11: =C11-B11 -> -0.30551442 | G11: =IF(E11="","",ROUND(ROUND(F11,1)-ROUND(E11,1),1)) | H11: 0.6 | I11: 0.29448558 | J11: =IF(H11="","",ABS(ROUND(I11,1)-H11)) -> 0.3 | K11: =SUM(J$5:J11) -> 1.4 | L11: 2021 reopening
A12: 2021-06 | B12: 0.92906629 | C12: 0.67370915 | D12: =C12-B12 -> -0.25535714 | E12: 5.3914514 | F12: 5.1248041 | G12: =IF(E12="","",ROUND(ROUND(F12,1)-ROUND(E12,1),1)) -> -0.3 | H12: 0.9 | I12: 0.64464286 | J12: =IF(H12="","",ABS(ROUND(I12,1)-H12)) -> 0.3 | K12: =SUM(J$5:J12) -> 1.7 | L12: 2021 reopening
A13: 2021-07 | B13: 0.48105235 | C13: 0.592155 | D13: =C13-B13 -> 0.11110265 | G13: =IF(E13="","",ROUND(ROUND(F13,1)-ROUND(E13,1),1)) | H13: 0.5 | I13: 0.61110265 | J13: =IF(H13="","",ABS(ROUND(I13,1)-H13)) -> 0.1 | K13: =SUM(J$5:J13) -> 1.8 | L13: 2021 reopening
A14: 2021-08 | B14: 0.20659114 | C14: 0.71807265 | D14: =C14-B14 -> 0.51148152 | E14: 5.2512716 | F14: 5.7885025 | G14: =IF(E14="","",ROUND(ROUND(F14,1)-ROUND(E14,1),1)) -> 0.5 | H14: 0.3 | I14: 0.81148152 | J14: =IF(H14="","",ABS(ROUND(I14,1)-H14)) -> 0.5 | K14: =SUM(J$5:J14) -> 2.3 | L14: 2021 reopening
A15: 2021-09 | B15: 0.27159709 | C15: 0.57447449 | D15: =C15-B15 -> 0.30287741 | G15: =IF(E15="","",ROUND(ROUND(F15,1)-ROUND(E15,1),1)) | H15: 0.4 | I15: 0.70287741 | J15: =IF(H15="","",ABS(ROUND(I15,1)-H15)) -> 0.3 | K15: =SUM(J$5:J15) -> 2.6 | L15: 2021 reopening
A16: 2021-10 | B16: 0.83081186 | C16: 0.46574007 | D16: =C16-B16 -> -0.36507178 | E16: 6.2218689 | F16: 5.8372781 | G16: =IF(E16="","",ROUND(ROUND(F16,1)-ROUND(E16,1),1)) -> -0.4 | H16: 0.9 | I16: 0.53492822 | J16: =IF(H16="","",ABS(ROUND(I16,1)-H16)) -> 0.4 | K16: =SUM(J$5:J16) -> 3 | L16: 2021 reopening
A17: 2021-11 | B17: 0.49134275 | C17: 0.3333862 | D17: =C17-B17 -> -0.15795655 | E17: 6.8090028 | F17: 6.6411159 | G17: =IF(E17="","",ROUND(ROUND(F17,1)-ROUND(E17,1),1)) -> -0.2 | H17: 0.8 | I17: 0.64204345 | J17: =IF(H17="","",ABS(ROUND(I17,1)-H17)) -> 0.2 | K17: =SUM(J$5:J17) -> 3.2 | L17: 2021 reopening
A18: 2021-12 | B18: 0.30725172 | C18: 0.17397965 | D18: =C18-B18 -> -0.13327206 | E18: 7.0364029 | F18: 6.8941902 | G18: =IF(E18="","",ROUND(ROUND(F18,1)-ROUND(E18,1),1)) -> -0.1 | H18: 0.5 | I18: 0.36672794 | J18: =IF(H18="","",ABS(ROUND(I18,1)-H18)) -> 0.1 | K18: =SUM(J$5:J18) -> 3.3 | L18: 2021 reopening
A19: 2022-01 | B19: 0.84145738 | C19: 0.73356404 | D19: =C19-B19 -> -0.10789334 | E19: 7.4798725 | F19: 7.3648765 | G19: =IF(E19="","",ROUND(ROUND(F19,1)-ROUND(E19,1),1)) -> -0.1 | H19: 0.6 | I19: 0.49210666 | J19: =IF(H19="","",ABS(ROUND(I19,1)-H19)) -> 0.1 | K19: =SUM(J$5:J19) -> 3.4 | L19: 2022 energy peak
A20: 2022-02 | B20: 0.91339793 | C20: 0.95777015 | D20: =C20-B20 -> 0.044372226 | E20: 7.8710639 | F20: 7.9184955 | G20: =IF(E20="","",ROUND(ROUND(F20,1)-ROUND(E20,1),1)) -> 0 | H20: 0.8 | I20: 0.84437223 | J20: =IF(H20="","",ABS(ROUND(I20,1)-H20)) -> 0 | K20: =SUM(J$5:J20) -> 3.4 | L20: 2022 energy peak
A21: 2022-03 | B21: 1.335138 | C21: 1.3269931 | D21: =C21-B21 -> -0.0081448766 | E21: 8.5424556 | F21: 8.5337314 | G21: =IF(E21="","",ROUND(ROUND(F21,1)-ROUND(E21,1),1)) -> 0 | H21: 1.2 | I21: 1.1918551 | J21: =IF(H21="","",ABS(ROUND(I21,1)-H21)) -> 0 | K21: =SUM(J$5:J21) -> 3.4 | L21: 2022 energy peak
A22: 2022-04 | B22: 0.5582531 | C22: 0.39863664 | D22: =C22-B22 -> -0.15961647 | E22: 8.2586293 | F22: 8.08679 | G22: =IF(E22="","",ROUND(ROUND(F22,1)-ROUND(E22,1),1)) -> -0.2 | H22: 0.3 | I22: 0.14038353 | J22: =IF(H22="","",ABS(ROUND(I22,1)-H22)) -> 0.2 | K22: =SUM(J$5:J22) -> 3.6 | L22: 2022 energy peak
A23: 2022-05 | B23: 1.1023524 | C23: 0.97208504 | D23: =C23-B23 -> -0.13026736 | E23: 8.5815115 | F23: 8.4416075 | G23: =IF(E23="","",ROUND(ROUND(F23,1)-ROUND(E23,1),1)) -> -0.2 | H23: 1 | I23: 0.86973264 | J23: =IF(H23="","",ABS(ROUND(I23,1)-H23)) -> 0.1 | K23: =SUM(J$5:J23) -> 3.7 | L23: 2022 energy peak
A24: 2022-06 | B24: 1.3736076 | C24: 1.2579835 | D24: =C24-B24 -> -0.11562408 | E24: 9.059758 | F24: 8.9353673 | G24: =IF(E24="","",ROUND(ROUND(F24,1)-ROUND(E24,1),1)) -> -0.2 | H24: 1.3 | I24: 1.1843759 | J24: =IF(H24="","",ABS(ROUND(I24,1)-H24)) -> 0.1 | K24: =SUM(J$5:J24) -> 3.8 | L24: 2022 energy peak
A25: 2022-07 | B25: -0.011811914 | C25: 0.21233043 | D25: =C25-B25 -> 0.22414235 | E25: 8.5248147 | F25: 8.7680935 | G25: =IF(E25="","",ROUND(ROUND(F25,1)-ROUND(E25,1),1)) -> 0.3 | H25: 0 | I25: 0.22414235 | J25: =IF(H25="","",ABS(ROUND(I25,1)-H25)) -> 0.2 | K25: =SUM(J$5:J25) -> 4 | L25: 2022 energy peak
A26: 2022-08 | B26: -0.035439928 | C26: 0.060028075 | D26: =C26-B26 -> 0.095468003 | E26: 8.2626925 | F26: 8.3660854 | G26: =IF(E26="","",ROUND(ROUND(F26,1)-ROUND(E26,1),1)) -> 0.1 | H26: 0.1 | I26: 0.195468 | J26: =IF(H26="","",ABS(ROUND(I26,1)-H26)) -> 0.1 | K26: =SUM(J$5:J26) -> 4.1 | L26: 2022 energy peak
A27: 2022-09 | B27: 0.21507845 | C27: 0.35424051 | D27: =C27-B27 -> 0.13916205 | E27: 8.2016696 | F27: 8.3519221 | G27: =IF(E27="","",ROUND(ROUND(F27,1)-ROUND(E27,1),1)) -> 0.2 | H27: 0.4 | I27: 0.53916205 | J27: =IF(H27="","",ABS(ROUND(I27,1)-H27)) -> 0.1 | K27: =SUM(J$5:J27) -> 4.2 | L27: 2022 energy peak
... A73: 2026-09 | B73: 0.58510956 | C73: 0.49837075 | D73: =C73-B73 -> -0.086738809 | E73: 3.7376847 | F73: 3.6482273 | G73: =IF(E73="","",ROUND(ROUND(F73,1)-ROUND(E73,1),1)) -> -0.1 | H73: 0.6 | I73: 0.51326119 | J73: =IF(H73="","",ABS(ROUND(I73,1)-H73)) -> 0.1 | K73: =SUM(J$5:J73) -> 7.4 | L73: 2025-26 tariff/energy
A75: SUMMARY — full sample
A76: NSA MoM mean |error| (pp) | B76: =SUMPRODUCT(ABS(D5:D73))/COUNT(D5:D73) -> 0.11093781
A77: NSA MoM RMSE (pp) | B77: =SQRT(SUMPRODUCT(D5:D73,D5:D73)/COUNT(D5:D73)) -> 0.16015412
A78: NSA MoM bias (pp) | B78: =AVERAGE(D5:D73) -> -0.0041605946
A79: YoY bracket exact-hit rate | B79: =COUNTIF(G5:G73,0)/COUNT(G5:G73) -> 0.33333333
A80: YoY within one bracket (±0.1) | B80: =SUMPRODUCT((G5:G73<>"")*(ABS(N(+G5:G73))<=0.1001))/SUMPRODUCT((G5:G73<>"")*1) -> 0.77777778
A81: SA MoM exact-hit rate (rounded) | B81: =COUNTIF(J5:J73,0)/COUNT(J5:J73) -> 0.34782609
A82: SA |error| per print (Bloomberg criterion) | B82: =AVERAGE(J5:J73) -> 0.10724638
A83: SA cumulative |error|, last 18 prints | B83: =SUM(J56:J73) -> 1.3
A84: SA cumulative |error|, last 12 prints | B84: =SUM(J62:J73) -> 0.9
A86: BY PERIOD
A87: Period | B87: n | C87: MAE NSA | D87: YoY exact | E87: YoY ±0.1 | F87: SA exact | G87: |SA err|/print
A88: 2021 reopening | B88: =COUNTIF(L5:L73,A88) -> 14 | C88: =SUMPRODUCT((L5:L73=A88)*ABS(D5:D73))/B88 -> 0.23041569 | D88: =SUMPRODUCT((L5:L73=A88)*(G5:G73<>"")*(ABS(N(+G5:G73))<0.0001))/SUMPRODUCT((L5:L73=A88)*(G5:G73<>"")) -> 0 | E88: =SUMPRODUCT((L5:L73=A88)*(G5:G73<>"")*(ABS(N(+G5:G73))<=0.1001))/SUMPRODUCT((L5:L73=A88)*(G5:G73<>"")) -> 0.375 | F88: =SUMPRODUCT((L5:L73=A88)*(J5:J73=0))/B88 -> 0.071428571 | G88: =SUMPRODUCT((L5:L73=A88)*J5:J73)/B88 -> 0.23571429
...

Sheet Brackets
A1: Kalshi KXCPIYOY-26SEP — model probability vs market price
A2: Kalshi contracts are 'Above X%' (strictly greater than the one-decimal BLS figure). Prices pulled from api.elections.kalshi.com on Oct 13 2026 ~12:30 ET. Blue = update with live quotes before trading.
A4: Model unrounded YoY (%) | B4: =Nowcast!B46 -> 3.6560451
A5: Model SD, YoY (pp) | B5: =Nowcast!B51 -> 0.099746172
A6: SD override (leave blank to use model)
A7: SD in use | B7: =IF(B6="",B5,B6) -> 0.099746172
A8: Kalshi taker fee per contract (approx, $) | B8: 0.0175
A10: Contract | B10: Strike X | C10: Settles YES if print ≥ | D10: NSA MoM needed (%) | E10: Model P(YES) | F10: Kalshi YES bid | G10: Kalshi YES ask | H10: Edge: model − ask (buy YES) | I10: Edge: (1−model) − (1−bid) (buy NO) | J10: Note
A11: KXCPIYOY-26SEP-T3.3 | B11: 3.3 | C11: =B11+0.1 -> 3.4 | D11: =((1+(B11+0.05)/100)*Nowcast!$B$5/Nowcast!$B$4-1)*100 -> 0.20920652 | E11: =1-NORMDIST(B11+0.05,$B$4,$B$7,TRUE()) -> 0.99892338 | F11: 0.97 | G11: 0.98 | H11: =E11-G11-$B$8 -> 0.0014233801 | I11: =(1-E11)-(1-F11)-$B$8 -> -0.04642338
A12: KXCPIYOY-26SEP-T3.4 | B12: 3.4 | C12: =B12+0.1 -> 3.5 | D12: =((1+(B12+0.05)/100)*Nowcast!$B$5/Nowcast!$B$4-1)*100 -> 0.30616753 | E12: =1-NORMDIST(B12+0.05,$B$4,$B$7,TRUE()) -> 0.98057134 | F12: 0.95 | G12: 0.96 | H12: =E12-G12-$B$8 -> 0.0030713435 | I12: =(1-E12)-(1-F12)-$B$8 -> -0.048071344
A13: KXCPIYOY-26SEP-T3.5 | B13: 3.5 | C13: =B13+0.1 -> 3.6 | D13: =((1+(B13+0.05)/100)*Nowcast!$B$5/Nowcast!$B$4-1)*100 -> 0.40312854 | E13: =1-NORMDIST(B13+0.05,$B$4,$B$7,TRUE()) -> 0.85614303 | F13: 0.87 | G13: 0.88 | H13: =E13-G13-$B$8 -> -0.041356969 | I13: =(1-E13)-(1-F13)-$B$8 -> -0.0036430314
A14: KXCPIYOY-26SEP-T3.6 | B14: 3.6 | C14: =B14+0.1 -> 3.7 | D14: =((1+(B14+0.05)/100)*Nowcast!$B$5/Nowcast!$B$4-1)*100 -> 0.50008956 | E14: =1-NORMDIST(B14+0.05,$B$4,$B$7,TRUE()) -> 0.5241632 | F14: 0.51 | G14: 0.52 | H14: =E14-G14-$B$8 -> -0.013336797 | I14: =(1-E14)-(1-F14)-$B$8 -> -0.031663203 | J14: The 3.6 line is the coin-flip: market 51–52¢.
A15: KXCPIYOY-26SEP-T3.7 | B15: 3.7 | C15: =B15+0.1 -> 3.8 | D15: =((1+(B15+0.05)/100)*Nowcast!$B$5/Nowcast!$B$4-1)*100 -> 0.59705057 | E15: =1-NORMDIST(B15+0.05,$B$4,$B$7,TRUE()) -> 0.17311181 | F15: 0.1 | G15: 0.11 | H15: =E15-G15-$B$8 -> 0.045611809 | I15: =(1-E15)-(1-F15)-$B$8 -> -0.090611809 | J15: Golden's 3.66 sits in the 3.7 bucket; a large player is reportedly on the other side.
A16: KXCPIYOY-26SEP-T3.8 | B16: 3.8 | C16: =B16+0.1 -> 3.9 | D16: =((1+(B16+0.05)/100)*Nowcast!$B$5/Nowcast!$B$4-1)*100 -> 0.69401158 | E16: =1-NORMDIST(B16+0.05,$B$4,$B$7,TRUE()) -> 0.025918542 | F16: 0 | G16: 0.01 | H16: =E16-G16-$B$8 -> -0.0015814577 | I16: =(1-E16)-(1-F16)-$B$8 -> -0.043418542
A17: KXCPIYOY-26SEP-T3.9 | B17: 3.9 | C17: =B17+0.1 -> 4 | D17: =((1+(B17+0.05)/100)*Nowcast!$B$5/Nowcast!$B$4-1)*100 -> 0.7909726 | E17: =1-NORMDIST(B17+0.05,$B$4,$B$7,TRUE()) -> 0.0016042157 | F17: 0 | G17: 0.01 | H17: =E17-G17-$B$8 -> -0.025895784 | I17: =(1-E17)-(1-F17)-$B$8 -> -0.019104216
A20: Rounded print | B20: Unrounded range | D20: NSA MoM range (%) | E20: Model P(bucket) | F20: Market-implied P (mid) | H20: Edge (model − market) | J20: Note
A21: ≤3.4 | B21: < 3.45 | D21: =TEXT(((1+3.45/100)*Nowcast!$B$5/Nowcast!$B$4-1)*100,"0.000")&" or less" -> 0.306 or less | E21: =NORMDIST(3.45,$B$4,$B$7,TRUE()) -> 0.019428656 | F21: =1-AVERAGE(F12:G12) -> 0.045 | H21: =E21-F21 -> -0.025571344 | J21: Positive edge = model thinks the bucket is more likely than the market does.
A22: 3.5 | B22: 3.45 to 3.55 | D22: =TEXT(((1+3.45/100)*Nowcast!$B$5/Nowcast!$B$4-1)*100,"0.000")&" to "&TEXT(((1+3.55/100)*Nowcast!$B$5/Nowcast!$B$4-1)*100,"0.000") -> 0.306 to 0.403 | E22: =NORMDIST(3.55,$B$4,$B$7,TRUE())-NORMDIST(3.45,$B$4,$B$7,TRUE()) -> 0.12442831 | F22: =AVERAGE(F12:G12)-AVERAGE(F13:G13) -> 0.08 | H22: =E22-F22 -> 0.044428312 | J22: The model's tails come straight from the SD assumption. Before acting on a tail edge, stress B6 (e.g., 0.08 and 0.15) and see if it survives.
A23: 3.6 | B23: 3.55 to 3.65 | D23: =TEXT(((1+3.55/100)*Nowcast!$B$5/Nowcast!$B$4-1)*100,"0.000")&" to "&TEXT(((1+3.65/100)*Nowcast!$B$5/Nowcast!$B$4-1)*100,"0.000") -> 0.403 to 0.500 | E23: =NORMDIST(3.65,$B$4,$B$7,TRUE())-NORMDIST(3.55,$B$4,$B$7,TRUE()) -> 0.33197983 | F23: =AVERAGE(F13:G13)-AVERAGE(F14:G14) -> 0.36 | H23: =E23-F23 -> -0.028020172 | J23: Golden's method: he buys the tail bucket when his model says it's underpriced, not the modal bucket.
A24: 3.7 | B24: 3.65 to 3.75 | D24: =TEXT(((1+3.65/100)*Nowcast!$B$5/Nowcast!$B$4-1)*100,"0.000")&" to "&TEXT(((1+3.75/100)*Nowcast!$B$5/Nowcast!$B$4-1)*100,"0.000") -> 0.500 to 0.597 | E24: =NORMDIST(3.75,$B$4,$B$7,TRUE())-NORMDIST(3.65,$B$4,$B$7,TRUE()) -> 0.35105139 | F24: =AVERAGE(F14:G14)-AVERAGE(F15:G15) -> 0.41 | H24: =E24-F24 -> -0.058948606
A25: 3.8 | B25: 3.75 to 3.85 | D25: =TEXT(((1+3.75/100)*Nowcast!$B$5/Nowcast!$B$4-1)*100,"0.000")&" to "&TEXT(((1+3.85/100)*Nowcast!$B$5/Nowcast!$B$4-1)*100,"0.000") -> 0.597 to 0.694 | E25: =NORMDIST(3.85,$B$4,$B$7,TRUE())-NORMDIST(3.75,$B$4,$B$7,TRUE()) -> 0.14719327 | F25: =AVERAGE(F15:G15)-AVERAGE(F16:G16) -> 0.1 | H25: =E25-F25 -> 0.047193267
A26: ≥3.9 | B26: ≥ 3.85 | D26: =TEXT(((1+3.85/100)*Nowcast!$B$5/Nowcast!$B$4-1)*100,"0.000")&" or more" -> 0.694 or more | E26: =1-NORMDIST(3.85,$B$4,$B$7,TRUE()) -> 0.025918542 | F26: =AVERAGE(F16:G16) -> 0.005 | H26: =E26-F26 -> 0.020918542
A27: Sum (check = 100%) | E27: =SUM(E21:E26) -> 1 | F27: =SUM(F21:F26) -> 1

Sheet Forecasters
A1: Where everyone sits — published Sept 2026 forecasts, converted to one scale
A2: Blue = as published. If a source gave only SA MoM, NSA MoM is derived with the model's SA−NSA gap (Nowcast). If only YoY was given, MoM is back-solved.
A4: Model SA−NSA gap for Sept (pp) | B4: =Nowcast!B44-Nowcast!B43 -> 0.10054622
A6: Source | B6: SA MoM (%) | C6: YoY (%) as published | D6: Derived NSA MoM (%) | E6: Implied unrounded YoY (%) | F6: Rounded YoY | G6: Core SA MoM | H6: Note / link
A7: THIS MODEL | B7: =Nowcast!B44 -> 0.60649721 | D7: =Nowcast!B43 -> 0.50595099 | E7: =(Nowcast!$B$4*(1+D7/100)/Nowcast!$B$5-1)*100 -> 3.6560451 | F7: =ROUND(E7,1) -> 3.7 | G7: =Nowcast!B57 -> 0.22781798 | H7: Bottom-up (Nowcast tab)
A8: Brian Golden (Kalshi) | C8: 3.66 | D8: =((1+C8/100)*Nowcast!$B$5/Nowcast!$B$4-1)*100 -> 0.50978566 | E8: =(Nowcast!$B$4*(1+D8/100)/Nowcast!$B$5-1)*100 -> 3.66 | F8: =ROUND(E8,1) -> 3.7 | H8: Bloomberg, Oct 13 2026. 'Not a math guy'; spreadsheet replica of BLS method.
A9: Bloomberg consensus | B9: 0.6 | C9: 3.6 | D9: =B9-$B$4 -> 0.49945378 | E9: =(Nowcast!$B$4*(1+D9/100)/Nowcast!$B$5-1)*100 -> 3.6493443 | F9: =ROUND(E9,1) -> 3.6 | G9: 0.2 | H9: Bloomberg article; FactSet also 3.6. Kiplinger: +0.6 / 3.6; core +0.2 / 2.5
A10: Consensus (crypto.news/Truflation note) | B10: 0.6 | C10: 3.7 | D10: =B10-$B$4 -> 0.49945378 | E10: =(Nowcast!$B$4*(1+D10/100)/Nowcast!$B$5-1)*100 -> 3.6493443 | F10: =ROUND(E10,1) -> 3.6 | G10: 0.2 | H10: Shows the consensus itself straddles the 3.6/3.7 line
A11: Cleveland Fed nowcast (Oct 2) | B11: 0.53 | C11: 3.6 | D11: =B11-$B$4 -> 0.42945378 | E11: =(Nowcast!$B$4*(1+D11/100)/Nowcast!$B$5-1)*100 -> 3.5771503 | F11: =ROUND(E11,1) -> 3.6 | G11: 0.2 | H11: jorgai.com summary; core YoY 2.39
A12: Deutsche Bank | B12: 0.57 | C12: 3.64 | D12: =B12-$B$4 -> 0.46945378 | E12: =(Nowcast!$B$4*(1+D12/100)/Nowcast!$B$5-1)*100 -> 3.618404 | F12: =ROUND(E12,1) -> 3.6 | G12: 0.2 | H12: FinancialJuice CPI prep Oct 12: SA motor fuel +9.6%
A13: Wells Fargo | B13: 0.59 | D13: =B13-$B$4 -> 0.48945378 | E13: =(Nowcast!$B$4*(1+D13/100)/Nowcast!$B$5-1)*100 -> 3.6390309 | F13: =ROUND(E13,1) -> 3.6 | G13: 0.2 | H13: FinancialJuice / Kiplinger: 'We estimate the CPI rose 0.59%'
A14: Credit Agricole | C14: 3.64 | D14: =((1+C14/100)*Nowcast!$B$5/Nowcast!$B$4-1)*100 -> 0.49039346 | E14: =(Nowcast!$B$4*(1+D14/100)/Nowcast!$B$5-1)*100 -> 3.64 | F14: =ROUND(E14,1) -> 3.6 | G14: 0.2 | H14: FinancialJuice
A15: Truflation (Oct 9) | B15: 0.48 | C15: 3.6 | D15: =B15-$B$4 -> 0.37945378 | E15: =(Nowcast!$B$4*(1+D15/100)/Nowcast!$B$5-1)*100 -> 3.5255832 | F15: =ROUND(E15,1) -> 3.5 | H15: crypto.news; gasoline +4.8% in their data
A16: XTech / Exponential-Tech (Oct 5) | B16: 0.5 | D16: =B16-$B$4 -> 0.39945378 | E16: =(Nowcast!$B$4*(1+D16/100)/Nowcast!$B$5-1)*100 -> 3.5462101 | F16: =ROUND(E16,1) -> 3.5 | G16: 0.2 | H16: Gasoline +10% SA / +7.4% NSA
A17: Kalshi market (mid) | H17: See Brackets: P(>3.6) ≈ 51.5%, P(>3.7) ≈ 10.5%
A20: Reading this table: a published YoY of 3.6 with SA MoM of 0.6 is internally inconsistent given the Sept 2025 base (0.6 SA ≈ 0.52 NSA ≈ 3.67 YoY). Several forecasters are quoting a rounded headline that their own MoM number doesn't support.

Sheet Sources
A1: Sources
A3: BLS CPI August 2026 release and Table 1: https://www.bls.gov/news.release/cpi.nr0.htm ; https://www.bls.gov/news.release/cpi.t01.htm
A4: BLS CPI September 2025 release (archived): https://www.bls.gov/news.release/archives/cpi_10242025.htm
A5: BLS Table 7 (12-month effects and standard errors): https://www.bls.gov/news.release/cpi.t07.htm
A6: BLS seasonal factors (official file, replace Nowcast col H when downloaded): https://www.bls.gov/web/cpi/cpi-seasonal-factors.xlsx
A7: BLS CPI Handbook of Methods: https://www.bls.gov/opub/hom/cpi/
A8: Kalshi market data API (prices as of Oct 13 2026): https://api.elections.kalshi.com/trade-api/v2/markets?event_ticker=KXCPIYOY-26SEP
A9: Bloomberg, 'Kalshi's Top Inflation Trader Beats Wall Street Banks From His Garage', Oct 13 2026: https://www.bloomberg.com/news/features/2026-10-13/kalshi-s-top-inflation-trader-beats-wall-street-banks-from-his-garage
A10: Federal Reserve FEDS 2026-010, 'Kalshi and the Rise of Macro Markets': https://www.federalreserve.gov/econres/feds/files/2026010pap.pdf
A11: FinancialJuice CPI prep (DB, Wells, Credit Agricole): https://features.financialjuice.com/2026/10/12/us-cpi-prep-14th-october/
A12: Kiplinger Sept CPI preview: https://www.kiplinger.com/investing/economy/cpi-report-september-2026-what-to-expect
A13: Admiral Markets previews (AAA gasoline, Manheim): https://admiralmarkets.com/analytics/traders-blog/us-cpi-preview-september-2026-forecasts-and-the-core-cpi-outlook ; https://admiralmarkets.com/analytics/traders-blog/us-cpi-september-2026-scenarios-fed-october
... A19: Release history (YoY by month): https://therighttrader.com/economic-calendar/cpi

Sheet Gasoline
A1: Gasoline — EIA weekly U.S. regular retail price (all formulations, $/gal) → monthly average → CPI NSA MoM proxy
A2: Source: EIA series EMM_EPMR_PTE_NUS_DPG, week-ending Monday dates. Blue = data (append new weeks at the bottom). Monthly table on the right recalculates.
A4: Week ending | B4: $/gal | D4: Month | E4: EIA avg $/gal | F4: EIA MoM % | G4: CPI gasoline NSA MoM % (actual) | H4: EIA − CPI (pp) | I4: Note
A5: 45845 | B5: 3.125 | D5: 2025-07 | E5: =AVERAGEIFS($B$5:$B$70,$A$5:$A$70,">="&DATE(2025,7,1),$A$5:$A$70,"<"&DATE(2025,8,1)) -> 3.12475
A6: 45852 | B6: 3.13 | D6: 2025-08 | E6: =AVERAGEIFS($B$5:$B$70,$A$5:$A$70,">="&DATE(2025,8,1),$A$5:$A$70,"<"&DATE(2025,9,1)) -> 3.1325 | F6: =(E6/E5-1)*100 -> 0.24801984 | I6: CPI actual = index-level NSA change from BLS Table 1 (Sep25: 285.595/282.358; Aug26: 359.738/350.846).
A7: 45859 | B7: 3.121 | D7: 2025-09 | E7: =AVERAGEIFS($B$5:$B$70,$A$5:$A$70,">="&DATE(2025,9,1),$A$5:$A$70,"<"&DATE(2025,10,1)) -> 3.1656 | F7: =(E7/E6-1)*100 -> 1.056664 | G7: 1.146 | H7: =F7-G7 -> -0.089335994 | I7: EIA − CPI residual over the two verifiable months: −0.09 and +0.67 → SE ≈ 0.6pp used on Nowcast.
A8: 45866 | B8: 3.123 | D8: 2025-10 | E8: =AVERAGEIFS($B$5:$B$70,$A$5:$A$70,">="&DATE(2025,10,1),$A$5:$A$70,"<"&DATE(2025,11,1)) -> 3.05975 | F8: =(E8/E7-1)*100 -> -3.3437579 | I8: BLS prices gasoline across the whole month; the EIA monthly average is the closest public proxy. Fill col G as each CPI prints to tighten the SE.
A9: 45873 | B9: 3.14 | D9: 2025-11 | E9: =AVERAGEIFS($B$5:$B$70,$A$5:$A$70,">="&DATE(2025,11,1),$A$5:$A$70,"<"&DATE(2025,12,1)) -> 3.0495 | F9: =(E9/E8-1)*100 -> -0.33499469
A10: 45880 | B10: 3.118 | D10: 2025-12 | E10: =AVERAGEIFS($B$5:$B$70,$A$5:$A$70,">="&DATE(2025,12,1),$A$5:$A$70,"<"&DATE(2026,1,1)) -> 2.8944 | F10: =(E10/E9-1)*100 -> -5.0860797
A11: 45887 | B11: 3.125 | D11: 2026-01 | E11: =AVERAGEIFS($B$5:$B$70,$A$5:$A$70,">="&DATE(2026,1,1),$A$5:$A$70,"<"&DATE(2026,2,1)) -> 2.8085 | F11: =(E11/E10-1)*100 -> -2.9677999
A12: 45894 | B12: 3.147 | D12: 2026-02 | E12: =AVERAGEIFS($B$5:$B$70,$A$5:$A$70,">="&DATE(2026,2,1),$A$5:$A$70,"<"&DATE(2026,3,1)) -> 2.9075 | F12: =(E12/E11-1)*100 -> 3.5250134
A13: 45901 | B13: 3.177 | D13: 2026-03 | E13: =AVERAGEIFS($B$5:$B$70,$A$5:$A$70,">="&DATE(2026,3,1),$A$5:$A$70,"<"&DATE(2026,4,1)) -> 3.6376 | F13: =(E13/E12-1)*100 -> 25.11092
A14: 45908 | B14: 3.192 | D14: 2026-04 | E14: =AVERAGEIFS($B$5:$B$70,$A$5:$A$70,">="&DATE(2026,4,1),$A$5:$A$70,"<"&DATE(2026,5,1)) -> 4.1025 | F14: =(E14/E13-1)*100 -> 12.780405
A15: 45915 | B15: 3.168 | D15: 2026-05 | E15: =AVERAGEIFS($B$5:$B$70,$A$5:$A$70,">="&DATE(2026,5,1),$A$5:$A$70,"<"&DATE(2026,6,1)) -> 4.47925 | F15: =(E15/E14-1)*100 -> 9.1834247
A16: 45922 | B16: 3.173 | D16: 2026-06 | E16: =AVERAGEIFS($B$5:$B$70,$A$5:$A$70,">="&DATE(2026,6,1),$A$5:$A$70,"<"&DATE(2026,7,1)) -> 4.0496 | F16: =(E16/E15-1)*100 -> -9.5920076
A17: 45929 | B17: 3.118 | D17: 2026-07 | E17: =AVERAGEIFS($B$5:$B$70,$A$5:$A$70,">="&DATE(2026,7,1),$A$5:$A$70,"<"&DATE(2026,8,1)) -> 3.93225 | F17: =(E17/E16-1)*100 -> -2.8978171
A18: 45936 | B18: 3.124 | D18: 2026-08 | E18: =AVERAGEIFS($B$5:$B$70,$A$5:$A$70,">="&DATE(2026,8,1),$A$5:$A$70,"<"&DATE(2026,9,1)) -> 4.058 | F18: =(E18/E17-1)*100 -> 3.1979147 | G18: 2.534 | H18: =F18-G18 -> 0.66391468
A19: 45943 | B19: 3.061 | D19: 2026-09 | E19: =AVERAGEIFS($B$5:$B$70,$A$5:$A$70,">="&DATE(2026,9,1),$A$5:$A$70,"<"&DATE(2026,10,1)) -> 4.35475 | F19: =(E19/E18-1)*100 -> 7.3127156 | I19: ← feeds Nowcast gasoline forecast (manually: see Nowcast F15)
A20: 45950 | B20: 3.019
A21: 45957 | B21: 3.035
A22: 45964 | B22: 3.019
A23: 45971 | B23: 3.056
A24: 45978 | B24: 3.062
A25: 45985 | B25: 3.061
A26: 45992 | B26: 2.985
A27: 45999 | B27: 2.94
A28: 46006 | B28: 2.895
A29: 46013 | B29: 2.841
A30: 46020 | B30: 2.811
A31: 46027 | B31: 2.796
... A70: 46300 | B70: 4.354

Sheet SeasonalFactors
A1: Official BLS 2026 seasonal factors used in the model (CPI-U, calculated with data through Dec 2025)
A2: Source: www.bls.gov/web/cpi/cpi-seasonal-factors.xlsx (downloaded Oct 13 2026). SA−NSA gap for Sept = (Aug factor / Sep factor − 1) × 100. Blue = as published.
A4: Series | B4: Aug factor | C4: Sep factor | D4: Sept gap (pp) | E4: Used for
A5: Gasoline (all types) | B5: 104.221 | C5: 101.759 | D5: =(B5/C5-1)*100 -> 2.419442 | E5: Gasoline
A6: Motor fuel | B6: 104.126 | C6: 101.651 | D6: =(B6/C6-1)*100 -> 2.4348014 | E6: Other motor fuel
A7: Fuel oil | B7: 97.427 | C7: 97.008 | D7: =(B7/C7-1)*100 -> 0.43192314 | E7: Fuel oil & other fuels (with propane)
A8: Propane, kerosene, and firewood | B8: 96.69 | C8: 97.065 | D8: =(B8/C8-1)*100 -> -0.38633905
A9: Electricity | B9: 101.51 | C9: 101.193 | D9: =(B9/C9-1)*100 -> 0.31326278 | E9: Electricity
A10: Utility (piped) gas service | B10: 99.254 | C10: 98.753 | D10: =(B10/C10-1)*100 -> 0.50732636 | E10: Utility gas
A11: Women's apparel | B11: 100.451 | C11: 103.185 | D11: =(B11/C11-1)*100 -> -2.6496099 | E11: Apparel (weighted avg ≈ −2.1)
A12: Men's and boys' apparel | B12: 99.371 | C12: 101.153 | D12: =(B12/C12-1)*100 -> -1.7616877
A13: Footwear | B13: 100.283 | C13: 101.409 | D13: =(B13/C13-1)*100 -> -1.1103551
A14: Girls' apparel | B14: 99.604 | C14: 105.437 | D14: =(B14/C14-1)*100 -> -5.5322135
A15: New vehicles | B15: 100.254 | C15: 100.136 | D15: =(B15/C15-1)*100 -> 0.11783974 | E15: New vehicles
A16: Used cars and trucks | B16: 101.998 | C16: 101.218 | D16: =(B16/C16-1)*100 -> 0.77061392 | E16: Used cars
A17: Rent of primary residence | B17: 99.928 | C17: 99.994 | D17: =(B17/C17-1)*100 -> -0.06600396 | E17: Rent
A18: Owners' equivalent rent of residences | B18: 99.984 | C18: 100.026 | D18: =(B18/C18-1)*100 -> -0.041989083 | E18: OER
A19: Other lodging away from home including hotels and motels | B19: 103.515 | C19: 100.579 | D19: =(B19/C19-1)*100 -> 2.9190984 | E19: Other shelter
A20: Medical care services | B20: 100.014 | C20: 99.997 | D20: =(B20/C20-1)*100 -> 0.01700051 | E20: Medical care services
A21: Motor vehicle insurance | B21: 99.811 | C21: 99.496 | D21: =(B21/C21-1)*100 -> 0.31659564 | E21: Motor vehicle insurance
A22: Airline fares | B22: 95.821 | C22: 96.623 | D22: =(B22/C22-1)*100 -> -0.83003012 | E22: Airline fares
A23: Public transportation | B23: 97.162 | C23: 97.809 | D23: =(B23/C23-1)*100 -> -0.66149332 | E23: Other transportation svcs
A24: Car and truck rental | B24: 105.128 | C24: 99.789 | D24: =(B24/C24-1)*100 -> 5.3502891
A25: Household furnishings and supplies | B25: 99.975 | C25: 100.18 | D25: =(B25/C25-1)*100 -> -0.20463166 | E25: Other core goods
A26: Personal care products | B26: 100.119 | C26: 100.435 | D26: =(B26/C26-1)*100 -> -0.31463135
A27: Tuition, other school fees, and childcare | B27: 100.162 | C27: 100.801 | D27: =(B27/C27-1)*100 -> -0.63392228 | E27: Other core services
A28: Day care and preschool | B28: 99.585 | C28: 100.865 | D28: =(B28/C28-1)*100 -> -1.269023
A29: Cable, satellite, and live streaming television service | B29: 99.998 | C29: 99.744 | D29: =(B29/C29-1)*100 -> 0.25465191
A30: Durables | B30: 100.882 | C30: 100.11 | D30: =(B30/C30-1)*100 -> 0.77115173 | E30: cross-check
A31: Nondurables less food, beverages, and apparel | B31: 101.306 | C31: 100.464 | D31: =(B31/C31-1)*100 -> 0.83811116 | E31: cross-check
A32: Rent of shelter | B32: 100.076 | C32: 100.012 | D32: =(B32/C32-1)*100 -> 0.063992321 | E32: cross-check
A36: Series with no published factor (Food at home, Food away, Apparel, Lodging away, Medical care commodities, Alcohol, Tobacco, Education, Communication, Recreation) are adjusted indirectly by the BLS, i.e. from their components. The Nowcast gap for those is a weight-averaged estimate from the sub-series above.
